Workbook

Sheet Coverage check
A1: National curriculum coverage check – lesson library vs statutory programmes of study
A2: Each row is a statutory NC area. Lesson counts are live COUNTIFS on the "Lessons mapped" tab, so they update if you re-tag lessons there. Red = gap (0 lessons), amber = thin (1–4).
A4: NC subject | B4: Year / key stage | C4: NC area | D4: Lessons in library | E4: Status | G4: Summary
A5: Mathematics | B5: Year 1 | C5: Number – number and place value | D5: =COUNTIFS('Lessons mapped'!$F:$F,$A5,'Lessons mapped'!$C:$C,$B5,'Lessons mapped'!$H:$H,$C5) -> 80 | E5: =IF(D5=0,"GAP – no lessons",IF(D5<5,"Thin","Covered")) -> Covered | G5: NC areas checked | H5: =COUNTA(C5:C189) -> 185
A6: Mathematics | B6: Year 1 | C6: Number – addition and subtraction | D6: =COUNTIFS('Lessons mapped'!$F:$F,$A6,'Lessons mapped'!$C:$C,$B6,'Lessons mapped'!$H:$H,$C6) -> 50 | E6: =IF(D6=0,"GAP – no lessons",IF(D6<5,"Thin","Covered")) -> Covered | G6: Covered (5+ lessons) | H6: =COUNTIF(E5:E189,"Covered") -> 172
A7: Mathematics | B7: Year 1 | C7: Number – multiplication and division | D7: =COUNTIFS('Lessons mapped'!$F:$F,$A7,'Lessons mapped'!$C:$C,$B7,'Lessons mapped'!$H:$H,$C7) -> 10 | E7: =IF(D7=0,"GAP – no lessons",IF(D7<5,"Thin","Covered")) -> Covered | G7: Thin (1–4 lessons) | H7: =COUNTIF(E5:E189,"Thin") -> 4
A8: Mathematics | B8: Year 1 | C8: Number – fractions | D8: =COUNTIFS('Lessons mapped'!$F:$F,$A8,'Lessons mapped'!$C:$C,$B8,'Lessons mapped'!$H:$H,$C8) -> 0 | E8: =IF(D8=0,"GAP – no lessons",IF(D8<5,"Thin","Covered")) -> GAP – no lessons | G8: Gaps (0 lessons) | H8: =COUNTIF(E5:E189,"GAP*") -> 9
A9: Mathematics | B9: Year 1 | C9: Measurement | D9: =COUNTIFS('Lessons mapped'!$F:$F,$A9,'Lessons mapped'!$C:$C,$B9,'Lessons mapped'!$H:$H,$C9) -> 25 | E9: =IF(D9=0,"GAP – no lessons",IF(D9<5,"Thin","Covered")) -> Covered
A10: Mathematics | B10: Year 1 | C10: Geometry – properties of shapes | D10: =COUNTIFS('Lessons mapped'!$F:$F,$A10,'Lessons mapped'!$C:$C,$B10,'Lessons mapped'!$H:$H,$C10) -> 15 | E10: =IF(D10=0,"GAP – no lessons",IF(D10<5,"Thin","Covered")) -> Covered
A11: Mathematics | B11: Year 1 | C11: Geometry – position and direction | D11: =COUNTIFS('Lessons mapped'!$F:$F,$A11,'Lessons mapped'!$C:$C,$B11,'Lessons mapped'!$H:$H,$C11) -> 5 | E11: =IF(D11=0,"GAP – no lessons",IF(D11<5,"Thin","Covered")) -> Covered
A12: Mathematics | B12: Year 2 | C12: Number – number and place value | D12: =COUNTIFS('Lessons mapped'!$F:$F,$A12,'Lessons mapped'!$C:$C,$B12,'Lessons mapped'!$H:$H,$C12) -> 20 | E12: =IF(D12=0,"GAP – no lessons",IF(D12<5,"Thin","Covered")) -> Covered
A13: Mathematics | B13: Year 2 | C13: Number – addition and subtraction | D13: =COUNTIFS('Lessons mapped'!$F:$F,$A13,'Lessons mapped'!$C:$C,$B13,'Lessons mapped'!$H:$H,$C13) -> 50 | E13: =IF(D13=0,"GAP – no lessons",IF(D13<5,"Thin","Covered")) -> Covered
A14: Mathematics | B14: Year 2 | C14: Number – multiplication and division | D14: =COUNTIFS('Lessons mapped'!$F:$F,$A14,'Lessons mapped'!$C:$C,$B14,'Lessons mapped'!$H:$H,$C14) -> 60 | E14: =IF(D14=0,"GAP – no lessons",IF(D14<5,"Thin","Covered")) -> Covered
A15: Mathematics | B15: Year 2 | C15: Number – fractions | D15: =COUNTIFS('Lessons mapped'!$F:$F,$A15,'Lessons mapped'!$C:$C,$B15,'Lessons mapped'!$H:$H,$C15) -> 10 | E15: =IF(D15=0,"GAP – no lessons",IF(D15<5,"Thin","Covered")) -> Covered
A16: Mathematics | B16: Year 2 | C16: Measurement | D16: =COUNTIFS('Lessons mapped'!$F:$F,$A16,'Lessons mapped'!$C:$C,$B16,'Lessons mapped'!$H:$H,$C16) -> 20 | E16: =IF(D16=0,"GAP – no lessons",IF(D16<5,"Thin","Covered")) -> Covered
A17: Mathematics | B17: Year 2 | C17: Geometry – properties of shapes | D17: =COUNTIFS('Lessons mapped'!$F:$F,$A17,'Lessons mapped'!$C:$C,$B17,'Lessons mapped'!$H:$H,$C17) -> 10 | E17: =IF(D17=0,"GAP – no lessons",IF(D17<5,"Thin","Covered")) -> Covered
A18: Mathematics | B18: Year 2 | C18: Geometry – position and direction | D18: =COUNTIFS('Lessons mapped'!$F:$F,$A18,'Lessons mapped'!$C:$C,$B18,'Lessons mapped'!$H:$H,$C18) -> 5 | E18: =IF(D18=0,"GAP – no lessons",IF(D18<5,"Thin","Covered")) -> Covered
A19: Mathematics | B19: Year 2 | C19: Statistics | D19: =COUNTIFS('Lessons mapped'!$F:$F,$A19,'Lessons mapped'!$C:$C,$B19,'Lessons mapped'!$H:$H,$C19) -> 0 | E19: =IF(D19=0,"GAP – no lessons",IF(D19<5,"Thin","Covered")) -> GAP – no lessons
A20: Mathematics | B20: Year 3 | C20: Number – number and place value | D20: =COUNTIFS('Lessons mapped'!$F:$F,$A20,'Lessons mapped'!$C:$C,$B20,'Lessons mapped'!$H:$H,$C20) -> 25 | E20: =IF(D20=0,"GAP – no lessons",IF(D20<5,"Thin","Covered")) -> Covered
... A115: English | B115: Year 6 | C115: Writing – vocabulary, grammar and punctuation | D115: =COUNTIFS('Lessons mapped'!$F:$F,$A115,'Lessons mapped'!$C:$C,$B115,'Lessons mapped'!$H:$H,$C115) -> 65 | E115: =IF(D115=0,"GAP – no lessons",IF(D115<5,"Thin","Covered")) -> Covered
A116: Mathematics | B116: KS3 | C116: Number | D116: =COUNTIFS('Lessons mapped'!$F:$F,$A116,'Lessons mapped'!$D:$D,$B116,'Lessons mapped'!$H:$H,$C116) -> 98 | E116: =IF(D116=0,"GAP – no lessons",IF(D116<5,"Thin","Covered")) -> Covered
A117: Mathematics | B117: KS3 | C117: Algebra | D117: =COUNTIFS('Lessons mapped'!$F:$F,$A117,'Lessons mapped'!$D:$D,$B117,'Lessons mapped'!$H:$H,$C117) -> 99 | E117: =IF(D117=0,"GAP – no lessons",IF(D117<5,"Thin","Covered")) -> Covered
A118: Mathematics | B118: KS3 | C118: Ratio, proportion and rates of change | D118: =COUNTIFS('Lessons mapped'!$F:$F,$A118,'Lessons mapped'!$D:$D,$B118,'Lessons mapped'!$H:$H,$C118) -> 33 | E118: =IF(D118=0,"GAP – no lessons",IF(D118<5,"Thin","Covered")) -> Covered
A119: Mathematics | B119: KS3 | C119: Geometry and measures | D119: =COUNTIFS('Lessons mapped'!$F:$F,$A119,'Lessons mapped'!$D:$D,$B119,'Lessons mapped'!$H:$H,$C119) -> 102 | E119: =IF(D119=0,"GAP – no lessons",IF(D119<5,"Thin","Covered")) -> Covered
A120: Mathematics | B120: KS3 | C120: Probability | D120: =COUNTIFS('Lessons mapped'!$F:$F,$A120,'Lessons mapped'!$D:$D,$B120,'Lessons mapped'!$H:$H,$C120) -> 27 | E120: =IF(D120=0,"GAP – no lessons",IF(D120<5,"Thin","Covered")) -> Covered
A121: Mathematics | B121: KS3 | C121: Statistics | D121: =COUNTIFS('Lessons mapped'!$F:$F,$A121,'Lessons mapped'!$D:$D,$B121,'Lessons mapped'!$H:$H,$C121) -> 30 | E121: =IF(D121=0,"GAP – no lessons",IF(D121<5,"Thin","Covered")) -> Covered
A122: English | B122: KS3 | C122: Reading – Shakespeare | D122: =COUNTIFS('Lessons mapped'!$F:$F,$A122,'Lessons mapped'!$D:$D,$B122,'Lessons mapped'!$H:$H,$C122) -> 66 | E122: =IF(D122=0,"GAP – no lessons",IF(D122<5,"Thin","Covered")) -> Covered
A123: English | B123: KS3 | C123: Reading – 19th-century / pre-1914 literature | D123: =COUNTIFS('Lessons mapped'!$F:$F,$A123,'Lessons mapped'!$D:$D,$B123,'Lessons mapped'!$H:$H,$C123) -> 45 | E123: =IF(D123=0,"GAP – no lessons",IF(D123<5,"Thin","Covered")) -> Covered
A124: English | B124: KS3 | C124: Reading – Post-1914 / contemporary fiction and drama | D124: =COUNTIFS('Lessons mapped'!$F:$F,$A124,'Lessons mapped'!$D:$D,$B124,'Lessons mapped'!$H:$H,$C124) -> 87 | E124: =IF(D124=0,"GAP – no lessons",IF(D124<5,"Thin","Covered")) -> Covered
A125: English | B125: KS3 | C125: Reading – Poetry | D125: =COUNTIFS('Lessons mapped'!$F:$F,$A125,'Lessons mapped'!$D:$D,$B125,'Lessons mapped'!$H:$H,$C125) -> 59 | E125: =IF(D125=0,"GAP – no lessons",IF(D125<5,"Thin","Covered")) -> Covered
A126: English | B126: KS3 | C126: Reading – Non-fiction | D126: =COUNTIFS('Lessons mapped'!$F:$F,$A126,'Lessons mapped'!$D:$D,$B126,'Lessons mapped'!$H:$H,$C126) -> 16 | E126: =IF(D126=0,"GAP – no lessons",IF(D126<5,"Thin","Covered")) -> Covered
A127: English | B127: KS3 | C127: Writing | D127: =COUNTIFS('Lessons mapped'!$F:$F,$A127,'Lessons mapped'!$D:$D,$B127,'Lessons mapped'!$H:$H,$C127) -> 86 | E127: =IF(D127=0,"GAP – no lessons",IF(D127<5,"Thin","Covered")) -> Covered
... A165: Science | B165: KS3 | C165: Physics – Space physics | D165: =COUNTIFS('Lessons mapped'!$F:$F,$A165,'Lessons mapped'!$D:$D,$B165,'Lessons mapped'!$H:$H,$C165) -> 8 | E165: =IF(D165=0,"GAP – no lessons",IF(D165<5,"Thin","Covered")) -> Covered
A166: Science | B166: KS4 | C166: Biology – Cell biology | D166: =COUNTIFS('Lessons mapped'!$F:$F,$A166,'Lessons mapped'!$D:$D,$B166,'Lessons mapped'!$H:$H,$C166&"*") -> 62 | E166: =IF(D166=0,"GAP – no lessons",IF(D166<5,"Thin","Covered")) -> Covered
A167: Science | B167: KS4 | C167: Biology – Transport systems | D167: =COUNTIFS('Lessons mapped'!$F:$F,$A167,'Lessons mapped'!$D:$D,$B167,'Lessons mapped'!$H:$H,$C167) -> 30 | E167: =IF(D167=0,"GAP – no lessons",IF(D167<5,"Thin","Covered")) -> Covered
A168: Science | B168: KS4 | C168: Biology – Health, disease and the development of medicines | D168: =COUNTIFS('Lessons mapped'!$F:$F,$A168,'Lessons mapped'!$D:$D,$B168,'Lessons mapped'!$H:$H,$C168) -> 35 | E168: =IF(D168=0,"GAP – no lessons",IF(D168<5,"Thin","Covered")) -> Covered
A169: Science | B169: KS4 | C169: Biology – Coordination and control | D169: =COUNTIFS('Lessons mapped'!$F:$F,$A169,'Lessons mapped'!$D:$D,$B169,'Lessons mapped'!$H:$H,$C169) -> 45 | E169: =IF(D169=0,"GAP – no lessons",IF(D169<5,"Thin","Covered")) -> Covered
A170: Science | B170: KS4 | C170: Biology – Photosynthesis | D170: =COUNTIFS('Lessons mapped'!$F:$F,$A170,'Lessons mapped'!$D:$D,$B170,'Lessons mapped'!$H:$H,$C170) -> 20 | E170: =IF(D170=0,"GAP – no lessons",IF(D170<5,"Thin","Covered")) -> Covered
A171: Science | B171: KS4 | C171: Biology – Ecosystems | D171: =COUNTIFS('Lessons mapped'!$F:$F,$A171,'Lessons mapped'!$D:$D,$B171,'Lessons mapped'!$H:$H,$C171) -> 30 | E171: =IF(D171=0,"GAP – no lessons",IF(D171<5,"Thin","Covered")) -> Covered
A172: Science | B172: KS4 | C172: Biology – Evolution, inheritance and variation | D172: =COUNTIFS('Lessons mapped'!$F:$F,$A172,'Lessons mapped'!$D:$D,$B172,'Lessons mapped'!$H:$H,$C172) -> 55 | E172: =IF(D172=0,"GAP – no lessons",IF(D172<5,"Thin","Covered")) -> Covered
...

Sheet Lessons mapped
A1: Lesson title | B1: Portal subject | C1: Year | D1: Key stage | E1: Portal topic (unit) | F1: NC subject | G1: NC strand | H1: NC area | I1: NC status | J1: Match confidence | K1: Notes | L1: Learning objective | M1: Oak URL
A2: Characters in 'A Superhero Like You' | B2: English | C2: Year 1 | D2: KS1 | E2: A superhero like you reading and writing | F2: English | G2: Reading | H2: Reading – comprehension | I2: Statutory NC content | J2: Medium | L2: I can discuss characters and events in the story. | M2: https://www.thenational.academy/teachers/programmes/english-primary-ks1/units/a-superhero-like-you-reading-and-writing/lessons/characters-in-a-superhero-like-you
A3: Describing yourself | B3: English | C3: Year 1 | D3: KS1 | E3: A superhero like you reading and writing | F3: English | G3: Reading | H3: Reading – comprehension | I3: Statutory NC content | J3: Medium | L3: I can describe my own skills and personality in a sentence. | M3: https://www.thenational.academy/teachers/programmes/english-primary-ks1/units/a-superhero-like-you-reading-and-writing/lessons/describing-yourself
A4: Exploring the idea of a superhero and predicting | B4: English | C4: Year 1 | D4: KS1 | E4: A superhero like you reading and writing | F4: English | G4: Reading | H4: Reading – comprehension | I4: Statutory NC content | J4: Medium | L4: I can make a prediction about a book using what I know about superheroes and the front cover. | M4: https://www.thenational.academy/teachers/programmes/english-primary-ks1/units/a-superhero-like-you-reading-and-writing/lessons/exploring-the-idea-of-a-superhero-and-predicting
A5: Introducing adjectives to describe people who help us | B5: English | C5: Year 1 | D5: KS1 | E5: A superhero like you reading and writing | F5: English | G5: Reading | H5: Reading – comprehension | I5: Statutory NC content | J5: Medium | L5: I can use adjectives to describe personality traits. | M5: https://www.thenational.academy/teachers/programmes/english-primary-ks1/units/a-superhero-like-you-reading-and-writing/lessons/introducing-adjectives-to-describe-people-who-help-us
A6: The theme of community in 'A Superhero Like You' | B6: English | C6: Year 1 | D6: KS1 | E6: A superhero like you reading and writing | F6: English | G6: Reading | H6: Reading – comprehension | I6: Statutory NC content | J6: Medium | L6: I can listen and respond to a story. | M6: https://www.thenational.academy/teachers/programmes/english-primary-ks1/units/a-superhero-like-you-reading-and-writing/lessons/the-theme-of-community-in-a-superhero-like-you
A7: Writing about your future job | B7: English | C7: Year 1 | D7: KS1 | E7: A superhero like you reading and writing | F7: English | G7: Writing | H7: Writing – composition | I7: Statutory NC content | J7: Medium | L7: I can write about what I want to be when I grow up. | M7: https://www.thenational.academy/teachers/programmes/english-primary-ks1/units/a-superhero-like-you-reading-and-writing/lessons/writing-about-your-future-job
A8: Writing captions about people who help us | B8: English | C8: Year 1 | D8: KS1 | E8: A superhero like you reading and writing | F8: English | G8: Writing | H8: Writing – composition | I8: Statutory NC content | J8: Medium | L8: I can name and write captions for people who help us in the community. | M8: https://www.thenational.academy/teachers/programmes/english-primary-ks1/units/a-superhero-like-you-reading-and-writing/lessons/writing-captions-about-people-who-help-us
A9: Writing simple sentences about people who help us | B9: English | C9: Year 1 | D9: KS1 | E9: A superhero like you reading and writing | F9: English | G9: Writing | H9: Writing – composition | I9: Statutory NC content | J9: Medium | L9: I can write a sentence about people who help me. | M9: https://www.thenational.academy/teachers/programmes/english-primary-ks1/units/a-superhero-like-you-reading-and-writing/lessons/writing-simple-sentences-about-people-who-help-us
A10: Characters and plot in the story 'Ada Twist, Scientist' | B10: English | C10: Year 1 | D10: KS1 | E10: Ada twist scientist reading and writing | F10: English | G10: Reading | H10: Reading – comprehension | I10: Statutory NC content | J10: Medium | L10: I can talk about the characters and plot in the story "Ada Twist, Scientist" to make a prediction. | M10: https://www.thenational.academy/teachers/programmes/english-primary-ks1/units/ada-twist-scientist-reading-and-writing/lessons/characters-and-plot-in-the-story-ada-twist-scientist
A11: Exploring aspirations and the future: 'Ada Twist, Scientist' | B11: English | C11: Year 1 | D11: KS1 | E11: Ada twist scientist reading and writing | F11: English | G11: Reading | H11: Reading – comprehension | I11: Statutory NC content | J11: Medium | L11: I can use a character's experience to consider what aspiration means and write about my future. | M11: https://www.thenational.academy/teachers/programmes/english-primary-ks1/units/ada-twist-scientist-reading-and-writing/lessons/exploring-aspirations-and-the-future-ada-twist-scientist
A12: The theme of resilience in 'Ada Twist, Scientist' | B12: English | C12: Year 1 | D12: KS1 | E12: Ada twist scientist reading and writing | F12: English | G12: Reading | H12: Reading – comprehension | I12: Statutory NC content | J12: Medium | L12: I can describe how a character is feeling at different points in the story "Ada Twist, Scientist". | M12: https://www.thenational.academy/teachers/programmes/english-primary-ks1/units/ada-twist-scientist-reading-and-writing/lessons/the-theme-of-resilience-in-ada-twist-scientist
A13: Using descriptive language to describe yourself | B13: English | C13: Year 1 | D13: KS1 | E13: Ada twist scientist reading and writing | F13: English | G13: Writing | H13: Writing – composition | I13: Statutory NC content | J13: Medium | L13: I can write descriptive sentences to describe my appearance and personality. | M13: https://www.thenational.academy/teachers/programmes/english-primary-ks1/units/ada-twist-scientist-reading-and-writing/lessons/using-descriptive-language-to-describe-yourself
... A5537: Using the tangent ratio | B5537: Maths | C5537: Year 9 | D5537: KS3 | E5537: Trigonometry | F5537: Mathematics | G5537: Geometry and measures | H5537: Geometry and measures | I5537: Statutory NC content | J5537: High | L5537: I can use the tangent ratio to find the missing side or angle in a right-angled triangle. | M5537: https://www.thenational.academy/teachers/programmes/maths-secondary-ks3/units/trigonometry/lessons/using-the-tangent-ratio
A5538: Area of a sector | B5538: Maths | C5538: Year 10 | D5538: KS4 | E5538: 2d and 3d shape compound shapes | F5538: Mathematics | G5538: Geometry and measures | H5538: Geometry and measures | I5538: Statutory NC content | J5538: High | K5538: Foundation tier | L5538: I can calculate the area of a sector. | M5538: https://www.thenational.academy/teachers/programmes/maths-secondary-ks4-foundation/units/2d-and-3d-shape-compound-shapes/lessons/area-of-a-sector
A5539: Area of compound shapes | B5539: Maths | C5539: Year 10 | D5539: KS4 | E5539: 2d and 3d shape compound shapes | F5539: Mathematics | G5539: Geometry and measures | H5539: Geometry and measures | I5539: Statutory NC content | J5539: High | K5539: Foundation tier | L5539: I can find the area of compound shapes involving circles in different ways. | M5539: https://www.thenational.academy/teachers/programmes/maths-secondary-ks4-foundation/units/2d-and-3d-shape-compound-shapes/lessons/area-of-compound-shapes
A5540: Calculating arc length | B5540: Maths | C5540: Year 10 | D5540: KS4 | E5540: 2d and 3d shape compound shapes | F5540: Mathematics | G5540: Geometry and measures | H5540: Geometry and measures | I5540: Statutory NC content | J5540: High | K5540: Foundation tier | L5540: I can calculate the arc length of a sector and the sector's perimeter. | M5540: https://www.thenational.academy/teachers/programmes/maths-secondary-ks4-foundation/units/2d-and-3d-shape-compound-shapes/lessons/calculating-arc-length
A5541: Checking and securing understanding of area for compound shapes | B5541: Maths | C5541: Year 10 | D5541: KS4 | E5541: 2d and 3d shape compound shapes | F5541: Mathematics | G5541: Geometry and measures | H5541: Geometry and measures | I5541: Statutory NC content | J5541: High | K5541: Foundation tier | L5541: I can calculate the area of compound shapes made from rectangles, triangles, parallelograms and trapeziums efficiently. | M5541: https://www.thenational.academy/teachers/programmes/maths-secondary-ks4-foundation/units/2d-and-3d-shape-compound-shapes/lessons/checking-and-securing-understanding-of-area-for-compound-shapes
A5542: Checking and securing understanding of area for standard shapes | B5542: Maths | C5542: Year 10 | D5542: KS4 | E5542: 2d and 3d shape compound shapes | F5542: Mathematics | G5542: Geometry and measures | H5542: Geometry and measures | I5542: Statutory NC content | J5542: High | K5542: Foundation tier | L5542: I can calculate the area of rectangles, triangles, parallelograms and trapeziums efficiently. | M5542: https://www.thenational.academy/teachers/programmes/maths-secondary-ks4-foundation/units/2d-and-3d-shape-compound-shapes/lessons/checking-and-securing-understanding-of-area-for-standard-shapes
A5543: Checking and securing understanding of circles | B5543: Maths | C5543: Year 10 | D5543: KS4 | E5543: 2d and 3d shape compound shapes | F5543: Mathematics | G5543: Geometry and measures | H5543: Geometry and measures | I5543: Statutory NC content | J5543: High | K5543: Foundation tier | L5543: I can identify the parts of a circle and calculate the perimeter and area of a circle. | M5543: https://www.thenational.academy/teachers/programmes/maths-secondary-ks4-foundation/units/2d-and-3d-shape-compound-shapes/lessons/checking-and-securing-understanding-of-circles
A5544: Checking and securing understanding of converting between metric and imperial measures | B5544: Maths | C5544: Year 10 | D5544: KS4 | E5544: 2d and 3d shape compound shapes | F5544: Mathematics | G5544: Geometry and measures | H5544: Geometry and measures | I5544: Statutory NC content | J5544: High | K5544: Foundation tier | L5544: I can convert between metric and imperial measurements. | M5544: https://www.thenational.academy/teachers/programmes/maths-secondary-ks4-foundation/units/2d-and-3d-shape-compound-shapes/lessons/checking-and-securing-understanding-of-converting-between-metric-and-imperial-measures
A5545: Checking and securing understanding of perimeter for compound shapes | B5545: Maths | C5545: Year 10 | D5545: KS4 | E5545: 2d and 3d shape compound shapes | F5545: Mathematics | G5545: Geometry and measures | H5545: Geometry and measures | I5545: Statutory NC content | J5545: High | K5545: Foundation tier | L5545: I can calculate the perimeter of compound shapes made from rectangles, triangles, parallelograms and trapeziums efficiently. | M5545: https://www.thenational.academy/teachers/programmes/maths-secondary-ks4-foundation/units/2d-and-3d-shape-compound-shapes/lessons/checking-and-securing-understanding-of-perimeter-for-compound-shapes
A5546: Checking and securing understanding of perimeter for standard shapes | B5546: Maths | C5546: Year 10 | D5546: KS4 | E5546: 2d and 3d shape compound shapes | F5546: Mathematics | G5546: Geometry and measures | H5546: Geometry and measures | I5546: Statutory NC content | J5546: High | K5546: Foundation tier | L5546: I can calculate the perimeter of rectangles, triangles, parallelograms and trapeziums efficiently. | M5546: https://www.thenational.academy/teachers/programmes/maths-secondary-ks4-foundation/units/2d-and-3d-shape-compound-shapes/lessons/checking-and-securing-understanding-of-perimeter-for-standard-shapes
A5547: Checking and securing understanding of scales and conversion | B5547: Maths | C5547: Year 10 | D5547: KS4 | E5547: 2d and 3d shape compound shapes | F5547: Mathematics | G5547: Geometry and measures | H5547: Geometry and measures | I5547: Statutory NC content | J5547: High | K5547: Foundation tier | L5547: I can read values from various scales and convert between units of measure. | M5547: https://www.thenational.academy/teachers/programmes/maths-secondary-ks4-foundation/units/2d-and-3d-shape-compound-shapes/lessons/checking-and-securing-understanding-of-scales-and-conversion
A5548: Perimeter and area in a contextual setting | B5548: Maths | C5548: Year 10 | D5548: KS4 | E5548: 2d and 3d shape compound shapes | F5548: Mathematics | G5548: Geometry and measures | H5548: Geometry and measures | I5548: Statutory NC content | J5548: High | K5548: Foundation tier | L5548: I can apply my knowledge of perimeter and area in order to solve various contextual scenarios. | M5548: https://www.thenational.academy/teachers/programmes/maths-secondary-ks4-foundation/units/2d-and-3d-shape-compound-shapes/lessons/perimeter-and-area-in-a-contextual-setting
A5549: Problem solving with 2D shapes | B5549: Maths | C5549: Year 10 | D5549: KS4 | E5549: 2d and 3d shape compound shapes | F5549: Mathematics | G5549: Geometry and measures | H5549: Geometry and measures | I5549: Statutory NC content | J5549: High | K5549: Foundation tier | L5549: I can use my understanding of 2D shapes to solve problems. | M5549: https://www.thenational.academy/teachers/programmes/maths-secondary-ks4-foundation/units/2d-and-3d-shape-compound-shapes/lessons/problem-solving-with-2d-shapes
... A5973: The sum and difference with algebraic vector notation | B5973: Maths | C5973: Year 11 | D5973: KS4 | E5973: Vectors | F5973: Mathematics | G5973: Geometry and measures | H5973: Geometry and measures | I5973: Statutory NC content | J5973: High | K5973: Higher tier | L5973: I can find the sum and difference with vectors written algebraically. | M5973: https://www.thenational.academy/teachers/programmes/maths-secondary-ks4-higher/units/vectors/lessons/the-sum-and-difference-with-algebraic-vector-notation
A5974: Development of new materials (non-statutory) | B5974: Science | C5974: Year 1 | D5974: KS1 | E5974: Everyday materials | F5974: Science | G5974: Statutory topic | H5974: Everyday materials | I5974: Statutory NC content | J5974: High | L5974: I can talk about different jobs linked to science. | M5974: https://www.thenational.academy/teachers/programmes/science-primary-ks1/units/everyday-materials/lessons/development-of-new-materials-non-statutory
A5975: Everyday objects and materials | B5975: Science | C5975: Year 1 | D5975: KS1 | E5975: Everyday materials | F5975: Science | G5975: Statutory topic | H5975: Everyday materials | I5975: Statutory NC content | J5975: High | L5975: I can name different objects and the materials they are made from. | M5975: https://www.thenational.academy/teachers/programmes/science-primary-ks1/units/everyday-materials/lessons/everyday-objects-and-materials
A5976: Material properties | B5976: Science | C5976: Year 1 | D5976: KS1 | E5976: Everyday materials | F5976: Science | G5976: Statutory topic | H5976: Everyday materials | I5976: Statutory NC content | J5976: High | L5976: I can describe simple properties of everyday materials. | M5976: https://www.thenational.academy/teachers/programmes/science-primary-ks1/units/everyday-materials/lessons/material-properties
A5977: Materials for recycling (Climate Change & Sustainability) | B5977: Science | C5977: Year 1 | D5977: KS1 | E5977: Everyday materials | F5977: Science | G5977: Statutory topic | H5977: Everyday materials | I5977: Statutory NC content | J5977: High | L5977: I can name and group different materials that can be recycled. | M5977: https://www.thenational.academy/teachers/programmes/science-primary-ks1/units/everyday-materials/lessons/materials-for-recycling
A5978: The 3 Rs (non-statutory - Climate Change & Sustainability) | B5978: Science | C5978: Year 1 | D5978: KS1 | E5978: Everyday materials | F5978: Science | G5978: Statutory topic | H5978: Everyday materials | I5978: Statutory NC content | J5978: High | L5978: I can describe materials and objects that can be reduced, reused and recycled. | M5978: https://www.thenational.academy/teachers/programmes/science-primary-ks1/units/everyday-materials/lessons/the-3-rs-non-statutory-climate-change-and-sustainability
A5979: Transparent and opaque materials: plan and do | B5979: Science | C5979: Year 1 | D5979: KS1 | E5979: Everyday materials | F5979: Science | G5979: Statutory topic | H5979: Everyday materials | I5979: Statutory NC content | J5979: High | L5979: I can plan and do an investigation to find out about transparent and opaque materials. | M5979: https://www.thenational.academy/teachers/programmes/science-primary-ks1/units/everyday-materials/lessons/transparent-and-opaque-materials-plan-and-do
A5980: Transparent and opaque materials: review | B5980: Science | C5980: Year 1 | D5980: KS1 | E5980: Everyday materials | F5980: Science | G5980: Statutory topic | H5980: Everyday materials | I5980: Statutory NC content | J5980: High | L5980: I can name transparent and opaque materials and talk about how they are useful. | M5980: https://www.thenational.academy/teachers/programmes/science-primary-ks1/units/everyday-materials/lessons/transparent-and-opaque-materials-review
A5981: Waterproof materials: plan and do | B5981: Science | C5981: Year 1 | D5981: KS1 | E5981: Everyday materials | F5981: Science | G5981: Statutory topic | H5981: Everyday materials | I5981: Statutory NC content | J5981: High | L5981: I can plan and do an investigation to find out about waterproof materials. | M5981: https://www.thenational.academy/teachers/programmes/science-primary-ks1/units/everyday-materials/lessons/waterproof-materials-plan-and-do
A5982: Waterproof materials: review | B5982: Science | C5982: Year 1 | D5982: KS1 | E5982: Everyday materials | F5982: Science | G5982: Statutory topic | H5982: Everyday materials | I5982: Statutory NC content | J5982: High | L5982: I can find out about how famous scientists investigate waterproof materials. | M5982: https://www.thenational.academy/teachers/programmes/science-primary-ks1/units/everyday-materials/lessons/waterproof-materials-review
A5983: Body parts for our senses | B5983: Science | C5983: Year 1 | D5983: KS1 | E5983: Human body parts | F5983: Science | G5983: Statutory topic | H5983: Animals, including humans | I5983: Statutory NC content | J5983: High | L5983: I can explain which parts of the human body we use for our five senses. | M5983: https://www.thenational.academy/teachers/programmes/science-primary-ks1/units/human-body-parts/lessons/body-parts-for-our-senses
A5984: Body parts on the inside | B5984: Science | C5984: Year 1 | D5984: KS1 | E5984: Human body parts | F5984: Science | G5984: Statutory topic | H5984: Animals, including humans | I5984: Statutory NC content | J5984: High | L5984: I can name different parts on the inside of the human body and talk about what jobs they do. | M5984: https://www.thenational.academy/teachers/programmes/science-primary-ks1/units/human-body-parts/lessons/body-parts-on-the-inside
A5985: Body parts on the outside | B5985: Science | C5985: Year 1 | D5985: KS1 | E5985: Human body parts | F5985: Science | G5985: Statutory topic | H5985: Animals, including humans | I5985: Statutory NC content | J5985: High | L5985: I can name different parts on the outside of the human body and talk about what jobs they do. | M5985: https://www.thenational.academy/teachers/programmes/science-primary-ks1/units/human-body-parts/lessons/body-parts-on-the-outside
... A6652: Water waves | B6652: Science | C6652: Year 9 | D6652: KS3 | E6652: Waves | F6652: Science | G6652: Physics | H6652: Physics – Waves | I6652: Statutory NC content | J6652: High | L6652: I can explain how water waves consist of oscillations of water and describe how water waves can superpose and reflect. | M6652: https://www.thenational.academy/teachers/programmes/science-secondary-ks3/units/waves/lessons/water-waves
...

Sheet Topics mapped
A1: NC subject | B1: Portal subject | C1: Key stage | D1: Oak programme | E1: Portal topic (unit) | F1: Years | G1: Lessons | H1: Main NC area | I1: All NC areas (lesson count) | J1: NC status | K1: Notes
A2: English | B2: English | C2: KS1 | D2: english-primary-ks1 | E2: A superhero like you reading and writing | F2: Y1 | G2: 8 | H2: Reading – comprehension | I2: Reading – comprehension (5); Writing – composition (3) | J2: Statutory NC content
A3: English | B3: English | C3: KS1 | D3: english-primary-ks1 | E3: Ada twist scientist reading and writing | F3: Y1 | G3: 5 | H3: Reading – comprehension | I3: Reading – comprehension (3); Writing – composition (2) | J3: Statutory NC content
A4: English | B4: English | C4: KS1 | D4: english-primary-ks1 | E4: Anna hibiscus song reading and writing | F4: Y1 | G4: 10 | H4: Writing – composition | I4: Writing – composition (5); Reading – comprehension (5) | J4: Statutory NC content
A5: English | B5: English | C5: KS1 | D5: english-primary-ks1 | E5: Capital letters | F5: Y1 | G5: 9 | H5: Writing – handwriting | I5: Writing – handwriting (9) | J5: Statutory NC content
A6: English | B6: English | C6: KS1 | D6: english-primary-ks1 | E6: Following and writing instructions to make a sandwich reading and writing | F6: Y1 | G6: 5 | H6: Reading – comprehension | I6: Reading – comprehension (3); Writing – composition (2) | J6: Statutory NC content
A7: English | B7: English | C7: KS1 | D7: english-primary-ks1 | E7: Jack and the beanstalk reading and writing | F7: Y1 | G7: 9 | H7: Writing – composition | I7: Writing – composition (6); Reading – comprehension (3) | J7: Statutory NC content
A8: English | B8: English | C8: KS1 | D8: english-primary-ks1 | E8: Looking after pets reading and writing | F8: Y1 | G8: 10 | H8: Reading – comprehension | I8: Reading – comprehension (5); Writing – composition (5) | J8: Statutory NC content
A9: English | B9: English | C9: KS1 | D9: english-primary-ks1 | E9: Numerals 1 10 | F9: Y1 | G9: 2 | H9: Writing – handwriting | I9: Writing – handwriting (2) | J9: Statutory NC content
A10: English | B10: English | C10: KS1 | D10: english-primary-ks1 | E10: Nursery rhymes reading poetry | F10: Y1 | G10: 5 | H10: Reading – comprehension | I10: Reading – comprehension (4); Spoken language (1) | J10: Statutory NC content
A11: English | B11: English | C11: KS1 | D11: english-primary-ks1 | E11: Paddington reading and writing | F11: Y1 | G11: 10 | H11: Reading – comprehension | I11: Reading – comprehension (6); Writing – composition (4) | J11: Statutory NC content
A12: English | B12: English | C12: KS1 | D12: english-primary-ks1 | E12: School trip writing a recount | F12: Y1 | G12: 5 | H12: Writing – composition | I12: Writing – composition (5) | J12: Statutory NC content
A13: English | B13: English | C13: KS1 | D13: english-primary-ks1 | E13: Simple sentences | F13: Y1 | G13: 7 | H13: Writing – vocabulary, grammar and punctuation | I13: Writing – vocabulary, grammar and punctuation (7) | J13: Statutory NC content
... A680: Mathematics | B680: Maths | C680: KS3 | D680: maths-secondary-ks3 | E680: Trigonometry | F680: Y9 | G680: 12 | H680: Geometry and measures | I680: Geometry and measures (12) | J680: Statutory NC content
A681: Mathematics | B681: Maths | C681: KS4 | D681: maths-secondary-ks4-foundation | E681: 2d and 3d shape compound shapes | F681: Y10 | G681: 12 | H681: Geometry and measures | I681: Geometry and measures (12) | J681: Statutory NC content | K681: Foundation tier
A682: Mathematics | B682: Maths | C682: KS4 | D682: maths-secondary-ks4-foundation | E682: Algebraic manipulation | F682: Y10 | G682: 13 | H682: Algebra | I682: Algebra (13) | J682: Statutory NC content | K682: Foundation tier
A683: Mathematics | B683: Maths | C683: KS4 | D683: maths-secondary-ks4-foundation | E683: Angles | F683: Y10 | G683: 10 | H683: Geometry and measures | I683: Geometry and measures (10) | J683: Statutory NC content | K683: Foundation tier
A684: Mathematics | B684: Maths | C684: KS4 | D684: maths-secondary-ks4-foundation | E684: Arithmetic procedures index laws | F684: Y10 | G684: 11 | H684: Number | I684: Number (11) | J684: Statutory NC content | K684: Foundation tier
A685: Mathematics | B685: Maths | C685: KS4 | D685: maths-secondary-ks4-foundation | E685: Bearings | F685: Y10 | G685: 6 | H685: Geometry and measures | I685: Geometry and measures (6) | J685: Statutory NC content | K685: Foundation tier
A686: Mathematics | B686: Maths | C686: KS4 | D686: maths-secondary-ks4-foundation | E686: Comparisons of numerical summaries of data | F686: Y10 | G686: 14 | H686: Statistics | I686: Statistics (14) | J686: Statutory NC content | K686: Foundation tier
A687: Mathematics | B687: Maths | C687: KS4 | D687: maths-secondary-ks4-foundation | E687: Further transformations | F687: Y10 | G687: 9 | H687: Geometry and measures | I687: Geometry and measures (9) | J687: Statutory NC content | K687: Foundation tier
A688: Mathematics | B688: Maths | C688: KS4 | D688: maths-secondary-ks4-foundation | E688: Graphical representations of data scatter graphs and time series | F688: Y10 | G688: 8 | H688: Statistics | I688: Statistics (8) | J688: Statutory NC content | K688: Foundation tier
A689: Mathematics | B689: Maths | C689: KS4 | D689: maths-secondary-ks4-foundation | E689: Linear graphs | F689: Y10 | G689: 8 | H689: Algebra | I689: Algebra (8) | J689: Statutory NC content | K689: Foundation tier
A690: Mathematics | B690: Maths | C690: KS4 | D690: maths-secondary-ks4-foundation | E690: Non linear graphs | F690: Y10 | G690: 5 | H690: Algebra | I690: Algebra (5) | J690: Statutory NC content | K690: Foundation tier
A691: Mathematics | B691: Maths | C691: KS4 | D691: maths-secondary-ks4-foundation | E691: Percentages | F691: Y10 | G691: 10 | H691: Ratio, proportion and rates of change | I691: Ratio, proportion and rates of change (10) | J691: Statutory NC content | K691: Foundation tier
A692: Mathematics | B692: Maths | C692: KS4 | D692: maths-secondary-ks4-foundation | E692: Plans and elevations | F692: Y10 | G692: 5 | H692: Geometry and measures | I692: Geometry and measures (5) | J692: Statutory NC content | K692: Foundation tier
... A741: Mathematics | B741: Maths | C741: KS4 | D741: maths-secondary-ks4-higher | E741: Vectors | F741: Y11 | G741: 8 | H741: Geometry and measures | I741: Geometry and measures (8) | J741: Statutory NC content | K741: Higher tier
A742: Science | B742: Science | C742: KS1 | D742: science-primary-ks1 | E742: Everyday materials | F742: Y1 | G742: 9 | H742: Everyday materials | I742: Everyday materials (9) | J742: Statutory NC content
A743: Science | B743: Science | C743: KS1 | D743: science-primary-ks1 | E743: Human body parts | F743: Y1 | G743: 6 | H743: Animals, including humans | I743: Animals, including humans (6) | J743: Statutory NC content
A744: Science | B744: Science | C744: KS1 | D744: science-primary-ks1 | E744: Identifying plants and their basic parts | F744: Y1 | G744: 7 | H744: Plants | I744: Plants (7) | J744: Statutory NC content
A745: Science | B745: Science | C745: KS1 | D745: science-primary-ks1 | E745: Naming and grouping animals | F745: Y1 | G745: 6 | H745: Animals, including humans | I745: Animals, including humans (6) | J745: Statutory NC content
A746: Science | B746: Science | C746: KS1 | D746: science-primary-ks1 | E746: Seasonal changes autumn and winter | F746: Y1 | G746: 5 | H746: Seasonal changes | I746: Seasonal changes (5) | J746: Statutory NC content
A747: Science | B747: Science | C747: KS1 | D747: science-primary-ks1 | E747: Seasonal changes spring and summer | F747: Y1 | G747: 5 | H747: Seasonal changes | I747: Seasonal changes (5) | J747: Statutory NC content
A748: Science | B748: Science | C748: KS1 | D748: science-primary-ks1 | E748: Growing plants | F748: Y2 | G748: 8 | H748: Plants | I748: Plants (8) | J748: Statutory NC content
A749: Science | B749: Science | C749: KS1 | D749: science-primary-ks1 | E749: Healthy me | F749: Y2 | G749: 7 | H749: Animals, including humans | I749: Animals, including humans (7) | J749: Statutory NC content
A750: Science | B750: Science | C750: KS1 | D750: science-primary-ks1 | E750: Introduction to food chains | F750: Y2 | G750: 4 | H750: Living things and their habitats | I750: Living things and their habitats (4) | J750: Statutory NC content
A751: Science | B751: Science | C751: KS1 | D751: science-primary-ks1 | E751: Living things and where they live | F751: Y2 | G751: 7 | H751: Living things and their habitats | I751: Living things and their habitats (7) | J751: Statutory NC content
A752: Science | B752: Science | C752: KS1 | D752: science-primary-ks1 | E752: New life | F752: Y2 | G752: 5 | H752: Animals, including humans | I752: Animals, including humans (5) | J752: Statutory NC content
A753: Science | B753: Science | C753: KS1 | D753: science-primary-ks1 | E753: Uses of everyday materials | F753: Y2 | G753: 7 | H753: Uses of everyday materials | I753: Uses of everyday materials (7) | J753: Statutory NC content
... A820: Science | B820: Science | C820: KS3 | D820: science-secondary-ks3 | E820: Waves | F820: Y9 | G820: 5 | H820: Physics – Waves | I820: Physics – Waves (5) | J820: Statutory NC content
...

Sheet Area × year
A1: NC subject | B1: NC strand | C1: NC area | D1: Y1 | E1: Y2 | F1: Y3 | G1: Y4 | H1: Y5 | I1: Y6 | J1: Y7 | K1: Y8 | L1: Y9 | M1: Y10 | N1: Y11 | O1: Total
A2: English | B2: Grammar and vocabulary | C2: Grammar and vocabulary | D2: 0 | E2: 0 | F2: 0 | G2: 0 | H2: 0 | I2: 0 | J2: 0 | K2: 5 | L2: 0 | M2: 0 | N2: 0 | O2: =SUM(D2:N2) -> 5
A3: English | B3: Reading | C3: Reading – 19th-century / pre-1914 literature | D3: 0 | E3: 0 | F3: 0 | G3: 0 | H3: 0 | I3: 0 | J3: 16 | K3: 29 | L3: 0 | M3: 48 | N3: 41 | O3: =SUM(D3:N3) -> 134
A4: English | B4: Reading | C4: Reading – Fiction and wider reading | D4: 0 | E4: 0 | F4: 0 | G4: 0 | H4: 0 | I4: 0 | J4: 29 | K4: 5 | L4: 20 | M4: 15 | N4: 14 | O4: =SUM(D4:N4) -> 83
A5: English | B5: Reading | C5: Reading – Non-fiction | D5: 0 | E5: 0 | F5: 0 | G5: 0 | H5: 0 | I5: 0 | J5: 0 | K5: 0 | L5: 16 | M5: 11 | N5: 13 | O5: =SUM(D5:N5) -> 40
A6: English | B6: Reading | C6: Reading – Poetry | D6: 0 | E6: 0 | F6: 0 | G6: 0 | H6: 0 | I6: 0 | J6: 12 | K6: 37 | L6: 10 | M6: 89 | N6: 54 | O6: =SUM(D6:N6) -> 202
A7: English | B7: Reading | C7: Reading – Post-1914 / contemporary fiction and drama | D7: 0 | E7: 0 | F7: 0 | G7: 0 | H7: 0 | I7: 0 | J7: 29 | K7: 0 | L7: 58 | M7: 65 | N7: 58 | O7: =SUM(D7:N7) -> 210
A8: English | B8: Reading | C8: Reading – Shakespeare | D8: 0 | E8: 0 | F8: 0 | G8: 0 | H8: 0 | I8: 0 | J8: 18 | K8: 24 | L8: 24 | M8: 38 | N8: 40 | O8: =SUM(D8:N8) -> 144
A9: English | B9: Reading | C9: Reading – comprehension | D9: 50 | E9: 43 | F9: 66 | G9: 75 | H9: 58 | I9: 67 | J9: 0 | K9: 0 | L9: 0 | M9: 0 | N9: 0 | O9: =SUM(D9:N9) -> 359
A10: English | B10: Spoken English | C10: Spoken English | D10: 0 | E10: 0 | F10: 0 | G10: 0 | H10: 0 | I10: 0 | J10: 9 | K10: 20 | L10: 17 | M10: 35 | N10: 12 | O10: =SUM(D10:N10) -> 93
A11: English | B11: Spoken language | C11: Spoken language | D11: 9 | E11: 15 | F11: 13 | G11: 16 | H11: 18 | I11: 12 | J11: 0 | K11: 0 | L11: 0 | M11: 0 | N11: 0 | O11: =SUM(D11:N11) -> 83
A12: English | B12: Writing | C12: Writing | D12: 0 | E12: 0 | F12: 0 | G12: 0 | H12: 0 | I12: 0 | J12: 35 | K12: 28 | L12: 23 | M12: 47 | N12: 38 | O12: =SUM(D12:N12) -> 171
A13: English | B13: Writing | C13: Writing – composition | D13: 52 | E13: 74 | F13: 121 | G13: 130 | H13: 132 | I13: 130 | J13: 0 | K13: 0 | L13: 0 | M13: 0 | N13: 0 | O13: =SUM(D13:N13) -> 639
... A121: Science | B121: Statutory topic | C121: Uses of everyday materials | D121: 0 | E121: 7 | F121: 0 | G121: 0 | H121: 0 | I121: 0 | J121: 0 | K121: 0 | L121: 0 | M121: 0 | N121: 0 | O121: =SUM(D121:N121) -> 7

Sheet Method & notes
A1: How this was built
A2: Source library: ActivityOS-lesson-library.numbers (7,470 Oak National Academy lessons).
A3: Reference: National curriculum in England programmes of study (DfE, gov.uk/government/collections/national-curriculum) – English, mathematics, science and languages.
A4: Portal topic = the Oak unit each lesson belongs to (taken from the lesson URL, because the "unit" column in the library is empty).
A6: Mapping rules
A7: Maths & science: mapped at topic (unit) level to the NC strand / statutory topic – primary maths uses the year-specific strand names (e.g. Y4 "Number – fractions (including decimals)").
A8: English: mapped lesson by lesson, because most English units mix reading and writing. Lesson titles containing writing verbs (write, plan, draft, edit, publish) go to Writing; literary essays and analytical responses stay under Reading.
A9: Languages KS2–KS3: NC languages PoS is not split into named strands, so lessons are tagged with the grammar/vocabulary focus of the unit, which is what the KS3 PoS lists.
A10: Languages KS4 and any "non-statutory" Oak units are flagged NOT IN NC – languages are only statutory at KS2–KS3; KS4 MFL follows the AQA GCSE themes instead.
A11: KS4 science: Combined, Biology, Chemistry and Physics courses all map to the same NC KS4 science areas; Space physics is separate-science only.
A13: Confidence
A14: High = the topic name clearly matches one NC area. Medium = a judgement call (e.g. a lesson that mixes reading and writing, or a GCSE topic that spans two NC areas). Spot-check Medium rows before relying on them.
... A18: The national curriculum is being rewritten after the Curriculum and Assessment Review; new programmes are expected for first teaching from September 2028. Store an NC version with each tag so you can remap later.
